Workbook

Sheet Cover
B2: Cover Sheet
C6: Kokoda Property: Corporate Portfolio Fund Model
C7: Updated: | E7: 45365
D10: Colour coding:
D11: Hardcodes
D12: Formula
D13: Link from another sheet
D14: Partial input / inconsistent formula
D15: Hyperlink
D18: Contents:
D19: Assumptions
D20: Historical Reconstruction
D21: Hypothetical
D22: Sensitivities

Sheet Key Features
B2: Cover Sheet
C6: Kokoda Property: Corporate Portfolio Fund Model
C7: Updated: | E7: 45365
D10: Key Features
D12: - Pooled Fund
D13: - Pays Quarterly distributions (in arrears) - [cash rate + 6.65% margin]
D14: - Quarterly redemption windows (after minimum 12mth freeze), capped at up to 2.5% of FUM per annum.
D15: - Three (3) year investment term (after which vote to extend, or elect to redeem or rollover to next Fund)
D17: - Establishment Fee [1%]
D18: - Ongoing Administration Fee [0.5%] p/a
D21: - Backend treasury (not promoted fund feature) - 85% max deployment rate (minimum 15% of investment funds allocated to cash reserve)
D23: defer interest in loan agreeement (HWLE and EY). Setup deferral to repayment on a single loan basis.
D24: Interest payable is the amount actually received by the Borrower under the Project Loan Agreement as at the Interest Payment Date (being the termination date, or earlier date of repayment of the loan in full).
D25: The amount actually received will be unable to be determined until the Interest Payment Date (as opposed to the amount payable under that agreement).
D26: We have then added clause 3.1(b) so that there is a cap on the interest return, being x% per annum, calculated on the principal outstanding from the commencement of the agreement until the Interest Payment Date.

Sheet Assumptions
B2: Assumptions
A8: * | B8: Hypothetical Fundraising Assumptions
E10: Year 1 | F10: Year 2 | G10: Year 3+
C11: Kokoda Capital Raise Inflows p.a. ($m) | E11: 50 | F11: 100 | G11: 150
E13: Quarter 1 | F13: Quarter 2 | G13: Quarter 3 | H13: Quarter 4
C14: Kokoda Capital Raise Inflows Pattern (qtrly cycle) | E14: 0.25 | F14: 0.25 | G14: 0.25 | H14: 0.25 | I14: % of annual raise amount, per defined period
A17: * | B17: Investment Parameters
C19: Cash Rate % p/a | E19: 0.0435
C21: Investment Margin % p/a | E21: 0.0665
C23: Gross Investment return offered (IRR % pa) | E23: =SUM(E19,E21) -> 0.11 | F23: including benchmark rate. Paid as quarterly coupon (in arrears)
C25: Coupon - cash distribution frequency (times per year) | E25: 4 | F25: 0 = off, 1 = annual, 2 = half yearly, 4 = quarterly
C27: Kokoda Property Establishment Fee - charged on entry (% of Investments) | E27: 0.01
C29: Kokoda Property Administration Fee - ongoing pa (% of Investments) | E29: 0.005 | F29: arithmatic average of fund periodic balance - at calendar year end
C31: Fund Term (years) | E31: 3 | F31: [Not used]
C33: Overall Cost of Funds to Kokoda (IMPLIED) %pa | E33: =E23/E37 -> 0.1375 | F33: Rate paid to investors / Net Deployment Rate
A35: * | B35: Portfolio Management
C37: Net Deployment Rate (Lend : Cash) | E37: 0.8 | F37: Amount of investment funds raised deployed in projects vs retained as cash
C39: Cash at bank (TD Rate) (%pa) | E39: 0.045
C41: Treasury - Lending Rate to Project SPVs (%pa) | E41: 0.15 | F41: Capitalised. This is how much the fund on lends to Kokoda projects.
C43: Initial non redemption period (mths from fund open) | E43: 12
C45: Maximum Redemption Amount (% of FUM p/a) | E45: 0.025 | F45: Assumed max redemptions per annum (calculated periodically, based on rolling 12mth periodic average FUM)
C47: Redemptions (x frequency per year) | E47: 4 | F47: 0 = off, 1 = annual, 2 = half yearly, 4 = quarterly
C49: Fund re-investment rate (% of matured funds) | E49: 0.65 | F49: [Not used] Amount of cash re-invested in the fund at end of maturity
A53: * | B53: Investment Manager Debt Underwriting Fund Assumptions
C56: Investment Term
D57: Underwriting Fund Investment Term (months) | E57: =Sensitivities!S21 -> 36
D58: Underwriting Fund Fund "Run Off" Time After Close (months) | E58: 6 | F58: Not currently used. Possible to model in fund close / run off period later if required
C60: Investment Profile
D61: Sell Down % | E61: =Sensitivities!S23 -> 1
D62: Retention % | E62: =Sensitivities!S24 -> 0
D63: Sell Down Time (months) | E63: =Sensitivities!S25 -> 3
C65: Gross Fund Size - Total ($m) | E65: =Sensitivities!S26 -> 50
C67: Line of Credit
D68: Line of Credit (% of Fund) | E68: =Sensitivities!S28 -> 0.5
D69: Line of Credit Size ($m) | E69: =Sensitivities!S29 -> 25
D70: Net Underwriting Fund Size ($m) | E70: =Sensitivities!S30 -> 25
C72: Investment Restrictions
D73: Maximum single investment size (% of Gross Fund value) | E73: 0.3 | F73: Not currently used. Possible to model in single exposure limits later if required
C75: Preferred Returns
D76: Margin Share - Net Underwriting Fund (%) | E76: =Sensitivities!S32 -> 0.35
...

Sheet Hypothetical
B2: Hypothetical | E2: Total | G2: Year | R2: Quarter
E3: (3 yrs) | G3: Y1 | H3: Y2 | I3: Y3 | J3: Y4 | K3: Y5 | R3: 1 | S3: 2 | T3: 3 | U3: 4 | V3: 5 | W3: 6 | X3: 7 | Y3: 8 | Z3: 9 | AA3: 10 | AB3: 11 | AC3: 12 | AD3: 13 | AE3: 14 | AF3: 15 | AG3: 16 | AH3: 17 | AI3: 18 | AJ3: 19 | AK3: 20
G4: 24/25 | H4: 25/26 | I4: 26/27 | R4: 1 | S4: 2 | T4: 3 | U4: 4 | V4: 1 | W4: 2 | X4: 3 | Y4: 4 | Z4: 1 | AA4: 2 | AB4: 3 | AC4: 4 | AD4: 1 | AE4: 2 | AF4: 3 | AG4: 4 | AH4: 1 | AI4: 2 | AJ4: 3 | AK4: 4
A6: * | B6: Calculations
A8: * | B8: Kokoda - Underlying Project Cashflows / Requirements (NOT USED)
C10: New Facility Loan Amount (Principal) | E10: =SUM(R10:AC10) -> 0 | G10: =SUM(R10:AC10) -> 0 | H10: =SUM(#REF!) -> #REF! | I10: =SUM(#REF!) -> #REF! | J10: =SUM(#REF!) -> #REF! | K10: =SUM(#REF!) -> #REF!
C11: New Facility Loan Amount (Facility Limit) | E11: =SUM(R11:AC11) -> 0 | G11: =SUM(R11:AC11) -> 0 | H11: =SUM(#REF!) -> #REF! | I11: =SUM(#REF!) -> #REF! | J11: =SUM(#REF!) -> #REF! | K11: =SUM(#REF!) -> #REF!
C13: Facility Repayment (Original Principal) | E13: =SUM(R13:AC13) -> 0 | G13: =SUM(R13:AC13) -> 0 | H13: =SUM(#REF!) -> #REF! | I13: =SUM(#REF!) -> #REF! | J13: =SUM(#REF!) -> #REF! | K13: =SUM(#REF!) -> #REF!
C14: Facility Repayment (Principal + Gross Interest) | E14: =SUM(R14:AC14) -> 0 | G14: =SUM(R14:AC14) -> 0 | H14: =SUM(#REF!) -> #REF! | I14: =SUM(#REF!) -> #REF! | J14: =SUM(#REF!) -> #REF! | K14: =SUM(#REF!) -> #REF!
C16: Book Size (Principal) assuming zero start | E16: =MAX(R16:AC16) -> 0 | G16: =AVERAGE(R16:AC16) -> #DIV/0! | H16: =AVERAGE(#REF!) -> #REF! | I16: =AVERAGE(#REF!) -> #REF! | J16: =AVERAGE(#REF!) -> #REF! | K16: =AVERAGE(#REF!) -> #REF! | Q16: 0
C17: Book Size (Facility) assuming zero start | E17: =MAX(R17:AC17) -> 0 | G17: =AVERAGE(R17:AC17) -> #DIV/0! | H17: =AVERAGE(#REF!) -> #REF! | I17: =AVERAGE(#REF!) -> #REF! | J17: =AVERAGE(#REF!) -> #REF! | K17: =AVERAGE(#REF!) -> #REF! | Q17: 0
A20: * | B20: Fund - Working Balances
C22: Kokoda Fund
C23: Opening Balance | E23: =AC23 -> 255.21303 | G23: =U23 -> 37.125 | H23: =Y23 -> 122.53817 | I23: =AC23 -> 255.21303 | J23: =X23 -> 98.2521 | K23: =AB23 -> 219.23112 | L23: =AF23 -> 0 | M23: =AA23 -> 183.04805 | N23: =AE23 -> 0 | O23: =AI23 -> 0 | R23: =Q30 -> 0 | S23: =R30 -> 12.375 | T23: =S30 -> 24.75 | U23: =T30 -> 37.125 | V23: =U30 -> 49.339603 | W23: =V30 -> 73.846351 | X23: =W30 -> 98.2521 | Y23: =X30 -> 122.53817 | ... AC23: =AB30 -> 255.21303
C24: Inflow - Gross Funds Raised | E24: =SUM(R24:AC24) -> 300 | G24: =SUM(R24:U24) -> 50 | H24: =SUM(V24:Y24) -> 100 | I24: =SUM(Z24:AC24) -> 150 | R24: =Assumptions!E11*Assumptions!E14 -> 12.5 | S24: =Assumptions!E11*Assumptions!F14 -> 12.5 | T24: =Assumptions!E11*Assumptions!G14 -> 12.5 | U24: =Assumptions!E11*Assumptions!H14 -> 12.5 | V24: =Assumptions!F11*Assumptions!E14 -> 25 | W24: =Assumptions!F11*Assumptions!F14 -> 25 | X24: =Assumptions!F11*Assumptions!G14 -> 25 | Y24: =Assumptions!F11*Assumptions!H14 -> 25 | Z24: =Assumptions!G11*Assumptions!E14 -> 37.5 | AA24: =Assumptions!G11*Assumptions!F14 -> 37.5 | AB24: =Assumptions!G11*Assumptions!G14 -> 37.5 | AC24: =Assumptions!G11*Assumptions!H14 -> 37.5
C25: Outflow - Establishment Fee | E25: =SUM(R25:AC25) -> -3 | G25: =SUM(R25:U25) -> -0.5 | H25: =SUM(V25:Y25) -> -1 | I25: =SUM(Z25:AC25) -> -1.5 | R25: =-R24*Assumptions!$E$27 -> -0.125 | S25: =-S24*Assumptions!$E$27 -> -0.125 | T25: =-T24*Assumptions!$E$27 -> -0.125 | U25: =-U24*Assumptions!$E$27 -> -0.125 | V25: =-V24*Assumptions!$E$27 -> -0.25 | W25: =-W24*Assumptions!$E$27 -> -0.25 | X25: =-X24*Assumptions!$E$27 -> -0.25 | Y25: =-Y24*Assumptions!$E$27 -> -0.25 | ... AC25: =-AC24*Assumptions!$E$27 -> -0.375
C26: Coupon (Entitlement) | E26: =SUM(R26:AC26) -> 33.616099 | G26: =SUM(R26:U26) -> 2.041875 | H26: =SUM(V26:Y26) -> 9.4593462 | I26: =SUM(Z26:AC26) -> 22.114878 | R26: =IF(ISERROR(Q30*Assumptions!$E$23/Assumptions!$E$25),0,(Q30*Assumptions!$E$23/Assumptions!$E$25)) -> 0 | S26: =IF(ISERROR(R30*Assumptions!$E$23/Assumptions!$E$25),0,(R30*Assumptions!$E$23/Assumptions!$E$25)) -> 0.3403125 | T26: =IF(ISERROR(S30*Assumptions!$E$23/Assumptions!$E$25),0,(S30*Assumptions!$E$23/Assumptions!$E$25)) -> 0.680625 | U26: =IF(ISERROR(T30*Assumptions!$E$23/Assumptions!$E$25),0,(T30*Assumptions!$E$23/Assumptions!$E$25)) -> 1.0209375 | V26: =IF(ISERROR(U30*Assumptions!$E$23/Assumptions!$E$25),0,(U30*Assumptions!$E$23/Assumptions!$E$25)) -> 1.3568391 | W26: =IF(ISERROR(V30*Assumptions!$E$23/Assumptions!$E$25),0,(V30*Assumptions!$E$23/Assumptions!$E$25)) -> 2.0307747 | X26: =IF(ISERROR(W30*Assumptions!$E$23/Assumptions!$E$25),0,(W30*Assumptions!$E$23/Assumptions!$E$25)) -> 2.7019328 | Y26: =IF(ISERROR(X30*Assumptions!$E$23/Assumptions!$E$25),0,(X30*Assumptions!$E$23/Assumptions!$E$25)) -> 3.3697998 | ... AC26: =IF(ISERROR(AB30*Assumptions!$E$23/Assumptions!$E$25),0,(AB30*Assumptions!$E$23/Assumptions!$E$25)) -> 7.0183584
C27: Coupon (Cash Paid) | E27: =SUM(R27:AC27) -> -33.616099 | G27: =SUM(R27:U27) -> -2.041875 | H27: =SUM(V27:Y27) -> -9.4593462 | I27: =SUM(Z27:AC27) -> -22.114878 | R27: =R52 -> 0 | S27: =S52 -> -0.3403125 | T27: =T52 -> -0.680625 | U27: =U52 -> -1.0209375 | V27: =V52 -> -1.3568391 | W27: =W52 -> -2.0307747 | X27: =X52 -> -2.7019328 | Y27: =Y52 -> -3.3697998 | ... AC27: =AC52 -> -7.0183584
C28: Outflow - Redemptions | E28: =SUM(R28:AC28) -> -6.0282821 | G28: =SUM(R28:U28) -> -0.16039736 | H28: =SUM(V28:Y28) -> -1.6544355 | I28: =SUM(Z28:AC28) -> -4.2134493 | R28: =-R45 -> 0 | S28: =-S45 -> 0 | T28: =-T45 -> 0 | U28: =-U45 -> -0.16039736 | V28: =-V45 -> -0.24325146 | W28: =-W45 -> -0.34425101 | X28: =-X45 -> -0.46392689 | Y28: =-Y45 -> -0.6030061 | ... AC28: =-AC45 -> -1.3663141
C29: N/A | E29: =SUM(R29:AC29) -> 0 | G29: =SUM(R29:AC29) -> 0 | H29: =SUM(V29:Y29) -> 0 | I29: =SUM(Z29:AC29) -> 0
C30: Kokoda Fund - Closing Balance | E30: =MAX(R30:AC30) -> 290.97172 | G30: =U30 -> 49.339603 | H30: =Y30 -> 146.68517 | I30: =AC30 -> 290.97172 | Q30: 0 | R30: =SUM(R23:R29) -> 12.375 | S30: =SUM(S23:S29) -> 24.75 | T30: =SUM(T23:T29) -> 37.125 | U30: =SUM(U23:U29) -> 49.339603 | V30: =SUM(V23:V29) -> 73.846351 | W30: =SUM(W23:W29) -> 98.2521 | X30: =SUM(X23:X29) -> 122.53817 | Y30: =SUM(Y23:Y29) -> 146.68517 | ... AC30: =SUM(AC23:AC29) -> 290.97172
C32: Gross Underwriting Fund - Change in balance | R32: =R30-Q30 -> 12.375 | S32: =S30-R30 -> 12.375 | T32: =T30-S30 -> 12.375 | U32: =U30-T30 -> 12.214603 | V32: =V30-U30 -> 24.506749 | W32: =W30-V30 -> 24.405749 | X32: =X30-W30 -> 24.286073 | Y32: =Y30-X30 -> 24.146994 | ... AC32: =AC30-AB30 -> 35.758686
C35: Deployment Loan Balance
C36: Opening Loan Balances | R36: =Q40 -> 0 | S36: =R40 -> 9.9 | T36: =S40 -> 20.17125 | U36: =T40 -> 30.827672 | V36: =U40 -> 41.755392 | W36: =V40 -> 62.926618 | X36: =W40 -> 84.810965 | Y36: =X40 -> 107.42023 | ... AC36: =AB40 -> 236.1663
C37: Further Advance | R37: =(R30-Q30)*Assumptions!$E$37 -> 9.9 | S37: =(S30-R30)*Assumptions!$E$37 -> 9.9 | T37: =(T30-S30)*Assumptions!$E$37 -> 9.9 | U37: =(U30-T30)*Assumptions!$E$37 -> 9.7716821 | V37: =(V30-U30)*Assumptions!$E$37 -> 19.605399 | W37: =(W30-V30)*Assumptions!$E$37 -> 19.524599 | X37: =(X30-W30)*Assumptions!$E$37 -> 19.428858 | Y37: =(Y30-X30)*Assumptions!$E$37 -> 19.317595 | ... AC37: =(AC30-AB30)*Assumptions!$E$37 -> 28.606949
C38: Interest on Loan (Capitalising) | R38: =IF(ISERROR(Q40*Assumptions!$E$41/Assumptions!$E$25),0,Q40*(Assumptions!$E$41/Assumptions!$E$25)) -> 0 | S38: =IF(ISERROR(R40*Assumptions!$E$41/Assumptions!$E$25),0,R40*(Assumptions!$E$41/Assumptions!$E$25)) -> 0.37125 | T38: =IF(ISERROR(S40*Assumptions!$E$41/Assumptions!$E$25),0,S40*(Assumptions!$E$41/Assumptions!$E$25)) -> 0.75642188 | U38: =IF(ISERROR(T40*Assumptions!$E$41/Assumptions!$E$25),0,T40*(Assumptions!$E$41/Assumptions!$E$25)) -> 1.1560377 | V38: =IF(ISERROR(U40*Assumptions!$E$41/Assumptions!$E$25),0,U40*(Assumptions!$E$41/Assumptions!$E$25)) -> 1.5658272 | W38: =IF(ISERROR(V40*Assumptions!$E$41/Assumptions!$E$25),0,V40*(Assumptions!$E$41/Assumptions!$E$25)) -> 2.3597482 | X38: =IF(ISERROR(W40*Assumptions!$E$41/Assumptions!$E$25),0,W40*(Assumptions!$E$41/Assumptions!$E$25)) -> 3.1804112 | Y38: =IF(ISERROR(X40*Assumptions!$E$41/Assumptions!$E$25),0,X40*(Assumptions!$E$41/Assumptions!$E$25)) -> 4.0282588 | ... AC38: =IF(ISERROR(AB40*Assumptions!$E$41/Assumptions!$E$25),0,AB40*(Assumptions!$E$41/Assumptions!$E$25)) -> 8.8562364
C39: Less Loan Repayments
C40: Closing Loan Balance | Q40: 0 | R40: =SUM(R36:R39) -> 9.9 | S40: =SUM(S36:S39) -> 20.17125 | T40: =SUM(T36:T39) -> 30.827672 | U40: =SUM(U36:U39) -> 41.755392 | V40: =SUM(V36:V39) -> 62.926618 | W40: =SUM(W36:W39) -> 84.810965 | X40: =SUM(X36:X39) -> 107.42023 | Y40: =SUM(Y36:Y39) -> 130.76609 | ... AC40: =SUM(AC36:AC39) -> 273.62949
C44: Redemptions
C45: Redemptions (rolling average of last 12mths FUM balances x max redemption rate p/period) | R45: 0 | S45: 0 | T45: 0 | U45: =AVERAGE(R40:U40)*Assumptions!$E$45/Assumptions!$E$47 -> 0.16039736 | V45: =AVERAGE(S40:V40)*Assumptions!$E$45/Assumptions!$E$47 -> 0.24325146 | W45: =AVERAGE(T40:W40)*Assumptions!$E$45/Assumptions!$E$47 -> 0.34425101 | X45: =AVERAGE(U40:X40)*Assumptions!$E$45/Assumptions!$E$47 -> 0.46392689 | Y45: =AVERAGE(V40:Y40)*Assumptions!$E$45/Assumptions!$E$47 -> 0.6030061 | Z45: =AVERAGE(W40:Z40)*Assumptions!$E$45/Assumptions!$E$47 -> 0.76212095 | AA45: =AVERAGE(X40:AA40)*Assumptions!$E$45/Assumptions!$E$47 -> 0.94192426 | AB45: =AVERAGE(Y40:AB40)*Assumptions!$E$45/Assumptions!$E$47 -> 1.14309 | AC45: =AVERAGE(Z40:AC40)*Assumptions!$E$45/Assumptions!$E$47 -> 1.3663141
C48: Cash Account
C49: Opening Cash Balance | E49: =Q55 -> 0 | R49: =Q55 -> 0 | S49: =R55 -> 2.475 | T49: =S55 -> 4.6375312 | U49: =T55 -> 6.4840785 | V49: =U55 -> 7.6962025 | W49: =V55 -> 11.132694 | X49: =W55 -> 13.832911 | Y49: =X55 -> 15.772672 | ... AC49: =AB55 -> 21.341712
C50: Inflow - Fund Contributions (Cash Portion) | E50: =SUM(R50:AC50) -> 59.4 | R50: =SUM(R24:R25)*(1-Assumptions!$E$37) -> 2.475 | S50: =SUM(S24:S25)*(1-Assumptions!$E$37) -> 2.475 | T50: =SUM(T24:T25)*(1-Assumptions!$E$37) -> 2.475 | U50: =SUM(U24:U25)*(1-Assumptions!$E$37) -> 2.475 | V50: =SUM(V24:V25)*(1-Assumptions!$E$37) -> 4.95 | W50: =SUM(W24:W25)*(1-Assumptions!$E$37) -> 4.95 | X50: =SUM(X24:X25)*(1-Assumptions!$E$37) -> 4.95 | Y50: =SUM(Y24:Y25)*(1-Assumptions!$E$37) -> 4.95 | ... AC50: =SUM(AC24:AC25)*(1-Assumptions!$E$37) -> 7.425
C51: Inflow - Bank Interest on Cash at Bank | E51: =SUM(R51:AC51) -> 1.5726536 | R51: =R49*(Assumptions!$E$39/Assumptions!$E$25) -> 0 | S51: =S49*(Assumptions!$E$39/Assumptions!$E$25) -> 0.02784375 | T51: =T49*(Assumptions!$E$39/Assumptions!$E$25) -> 0.052172227 | U51: =U49*(Assumptions!$E$39/Assumptions!$E$25) -> 0.072945883 | V51: =V49*(Assumptions!$E$39/Assumptions!$E$25) -> 0.086582278 | W51: =W49*(Assumptions!$E$39/Assumptions!$E$25) -> 0.12524281 | X51: =X49*(Assumptions!$E$39/Assumptions!$E$25) -> 0.15562025 | Y51: =Y49*(Assumptions!$E$39/Assumptions!$E$25) -> 0.17744256 | ... AC51: =AC49*(Assumptions!$E$39/Assumptions!$E$25) -> 0.24009425
C52: Outflow - Less Investor Coupon Paid | E52: =SUM(R52:AC52) -> -33.616099 | R52: =-R26 -> 0 | S52: =-S26 -> -0.3403125 | T52: =-T26 -> -0.680625 | U52: =-U26 -> -1.0209375 | V52: =-V26 -> -1.3568391 | W52: =-W26 -> -2.0307747 | X52: =-X26 -> -2.7019328 | Y52: =-Y26 -> -3.3697998 | ... AC52: =-AC26 -> -7.0183584
C53: Outflow - Less Redemptions | E53: =SUM(R53:AC53) -> -6.0282821 | R53: =-R45 -> 0 | S53: =-S45 -> 0 | T53: =-T45 -> 0 | U53: =-U45 -> -0.16039736 | V53: =-V45 -> -0.24325146 | W53: =-W45 -> -0.34425101 | X53: =-X45 -> -0.46392689 | Y53: =-Y45 -> -0.6030061 | ... AC53: =-AC45 -> -1.3663141
C54: Outflow - Annual Administration Fee | E54: =SUM(R54:AC54) -> -1.8917191 | R54: =-R62 -> 0 | S54: =-S62 -> 0 | T54: =-T62 -> 0 | U54: =-U62 -> -0.154487 | V54: =-V62 -> 0 | W54: =-W62 -> 0 | X54: =-X62 -> 0 | Y54: =-Y62 -> -0.55165224 | ... AC54: =-AC62 -> -1.1855799
C55: Closing Cash Balance | E55: =AC55 -> 19.436553 | Q55: 0 | R55: =SUM(R49:R54) -> 2.475 | S55: =SUM(S49:S54) -> 4.6375312 | T55: =SUM(T49:T54) -> 6.4840785 | U55: =SUM(U49:U54) -> 7.6962025 | V55: =SUM(V49:V54) -> 11.132694 | W55: =SUM(W49:W54) -> 13.832911 | X55: =SUM(X49:X54) -> 15.772672 | Y55: =SUM(Y49:Y54) -> 16.375656 | ... AC55: =SUM(AC49:AC54) -> 19.436553
C58: Kokoda - Management Fees
C59: Establishment Fee - Incremental | E59: =SUM(R59:AC59) -> 3 | G59: =SUM(R59:U59) -> 0.5 | H59: =SUM(V59:Y59) -> 1 | I59: =SUM(Z59:AC59) -> 1.5 | J59: =AVERAGE(#REF!) -> #REF! | K59: =AVERAGE(#REF!) -> #REF! | R59: =-R25 -> 0.125 | S59: =-S25 -> 0.125 | T59: =-T25 -> 0.125 | U59: =-U25 -> 0.125 | V59: =-V25 -> 0.25 | W59: =-W25 -> 0.25 | X59: =-X25 -> 0.25 | Y59: =-Y25 -> 0.25 | ... AC59: =-AC25 -> 0.375
...

Sheet Sensitivities
B2: Sensitivities
E5: = CHANGE FROM BASE CASE ASSUMPTION | O5: CTRL-R to run macro
A6: * | B6: ASSUMPTIONS
E8: Base | G8: Scenario | I8: Scenario | K8: Scenario | M8: Scenario | O8: Scenario | Q8: Scenario | S8: MODEL
E9: Scenario | G9: #1 | I9: #2 | K9: #3 | M9: #4 | O9: #5 | Q9: #6 | S9: DRIVERS
B11: Property Lending Assumptions
D13: Gross return on debt facilities (IRR % pa) | E13: 0.2436 | G13: 0.2436 | I13: 0.2436 | K13: 0.2436 | M13: 0.2436 | O13: 0.2436 | Q13: 0.2436 | S13: 0.2436
D14: Net pre-tax investor return on debt facilities (IRR % pa) | E14: 0.19 | G14: 0.19 | I14: 0.19 | K14: 0.19 | M14: 0.19 | O14: 0.19 | Q14: 0.19 | S14: 0.19
D15: Wingate Property Establishment Fee (% of Facility) | E15: 0.0175 | G15: 0.0175 | I15: 0.0175 | K15: 0.0175 | M15: 0.0175 | O15: 0.0175 | Q15: 0.0175 | S15: 0.0175
D16: Debt facility term (months) | E16: 18 | G16: 18 | I16: 18 | K16: 18 | M16: 18 | O16: 18 | Q16: 18 | S16: 18
B18: Property Debt Underwriting Fund Assumptions
C20: Investment Term
D21: Underwriting Fund Investment Term (months) | E21: 36 | G21: 36 | I21: 36 | K21: 24 | M21: 36 | O21: 36 | Q21: 36 | S21: 36
C22: Investment Profile
D23: Sell Down % | E23: 1 | G23: 1 | I23: 1 | K23: 1 | M23: 1 | O23: 1 | Q23: 1 | S23: 1
D24: Retention % | E24: =1-E23 -> 0 | G24: =1-G23 -> 0 | I24: =1-I23 -> 0 | K24: =1-K23 -> 0 | M24: =1-M23 -> 0 | O24: =1-O23 -> 0 | Q24: =1-Q23 -> 0 | S24: 0
D25: Sell Down Time (months) | E25: 3 | G25: 3 | I25: 2 | K25: 3 | M25: 3 | O25: 3 | Q25: 3 | S25: 3
C26: Gross Fund Size - Total ($m) | E26: 50 | G26: 30 | I26: 50 | K26: 50 | M26: 50 | O26: 50 | Q26: 50 | S26: 50
C27: Line of Credit
D28: Line of Credit (% of Fund) | E28: 0.5 | G28: 0.5 | I28: 0.5 | K28: 0.5 | M28: 0.5 | O28: 0.3 | Q28: 0.5 | S28: 0.5
D29: Line of Credit Size ($m) | E29: =E28*E26 -> 25 | G29: =G28*G26 -> 15 | I29: =I28*I26 -> 25 | K29: =K28*K26 -> 25 | M29: =M28*M26 -> 25 | O29: =O28*O26 -> 15 | Q29: =Q28*Q26 -> 25 | S29: 25
D30: Net Underwriting Fund Size ($m) | E30: =E26-E29 -> 25 | G30: =G26-G29 -> 15 | I30: =I26-I29 -> 25 | K30: =K26-K29 -> 25 | M30: =M26-M29 -> 25 | O30: =O26-O29 -> 35 | Q30: =Q26-Q29 -> 25 | S30: 25
C31: Preferred Returns
D32: Margin Share - Net Underwriting Fund (%) | E32: 0.2 | G32: 0.2 | I32: 0.2 | K32: 0.2 | M32: 0.2 | O32: 0.2 | Q32: 0.35 | S32: 0.35
D33: Margin Share - Line of Credit (%) | E33: 0.05 | G33: 0.05 | I33: 0.05 | K33: 0.05 | M33: 0.05 | O33: 0.05 | Q33: 0.15 | S33: 0.15
D34: Margin Share - Gross Underwriting Fund (%) | E34: =SUM(E32:E33) -> 0.25 | G34: =SUM(G32:G33) -> 0.25 | I34: =SUM(I32:I33) -> 0.25 | K34: =SUM(K32:K33) -> 0.25 | M34: =SUM(M32:M33) -> 0.25 | O34: =SUM(O32:O33) -> 0.25 | Q34: =SUM(Q32:Q33) -> 0.5 | S34: 0.5
D35: Net Underwriting Fund - Preferred Return (IRR % pa) | E35: =E14+(E13-E14)*E32 -> 0.20072 | G35: =G14+(G13-G14)*G32 -> 0.20072 | I35: =I14+(I13-I14)*I32 -> 0.20072 | K35: =K14+(K13-K14)*K32 -> 0.20072 | M35: =M14+(M13-M14)*M32 -> 0.20072 | O35: =O14+(O13-O14)*O32 -> 0.20072 | Q35: =Q14+(Q13-Q14)*Q32 -> 0.20876 | S35: 0.20876
D36: Net Underwriting Fund - Interest Earned on Undrawn (IRR % pa) | E36: 0.035 | G36: 0.035 | I36: 0.035 | K36: 0.035 | M36: 0.035 | O36: 0.035 | Q36: 0.035 | S36: 0.035
D37: Line of Credit - Preferred Return (IRR % pa) | E37: =E14+(E13-E14)*E33 -> 0.19268 | G37: =G14+(G13-G14)*G33 -> 0.19268 | I37: =I14+(I13-I14)*I33 -> 0.19268 | K37: =K14+(K13-K14)*K33 -> 0.19268 | M37: =M14+(M13-M14)*M33 -> 0.19268 | O37: =O14+(O13-O14)*O33 -> 0.19268 | Q37: =Q14+(Q13-Q14)*Q33 -> 0.19804 | S37: 0.19804
C38: Line of Credit Charge
D39: Line of Credit Charge (% of Unused Line of Credit pa) | E39: 0.01 | G39: 0.01 | I39: 0.01 | K39: 0.01 | M39: 0.0125 | O39: 0.01 | Q39: 0.01 | S39: 0.01
C40: Fund Manager Fees
D41: Administration Fee - Net Underwriting Fund (% pa ex GST) | E41: 0.005 | G41: 0.005 | I41: 0.005 | K41: 0.005 | M41: 0.005 | O41: 0.005 | Q41: 0.005 | S41: 0.005
D42: Administration Fee - LOC (% pa ex GST) | E42: 0 | G42: 0 | I42: 0 | K42: 0 | M42: 0 | O42: 0 | Q42: 0 | S42: 0
C43: Distributions
D44: Net Underwriting Fund Distribution Frequency (Distributions p/a) | E44: 2 | G44: 2 | I44: 2 | K44: 2 | M44: 2 | O44: 2 | Q44: 2 | S44: 2
A46: * | B46: RESULTS
B48: Program Economics
C50: Underwriting Fund
D51: Peak Size | E51: 25 | G51: 15 | I51: 25 | K51: 25 | M51: 25 | O51: 35 | Q51: 25 | S51: =Hypothetical!E113 -> #REF!
...
